Workbook

Sheet Inputs
A1: LINE AI Chat — 五層架構 TCO 成本模型（Inputs 驅動全表；黃底可調）
A2: 參數 | B2: 值 | C2: 單位 | D2: 說明 / 來源
A3: FX_USD_TWD | B3: 32 | C3: NT$/US$ | D3: 匯率假設
A4: msgs_current | B4: 1000 | C4: 則/月 | D4: 目前流量上限（使用者：每月 < 1,000）
A5: hit_L1 | B5: 0.3 | C5: % | D5: Postback / 圖文選單命中率（可調）
A6: hit_L2 | B6: 0.25 | C6: % | D6: Keyword / Regex / Rule 命中率
A7: hit_L3 | B7: 0.2 | C7: % | D7: Semantic FAQ 直接回答命中率
A8: hit_L4 | B8: 0.2 | C8: % | D8: Cheap LLM 解決比例
A9: hit_L5 | B9: 0.05 | C9: % | D9: 升級到 Advanced / 真人 的比例（最大槓桿）
A10: CHECK_hit_sum | B10: =IF(ABS(SUM(B5:B9)-1)>0.001,"hit rates ≠ 100%","OK") | D10: 五層命中率必須合計 100%
A11: —— Tokens / 則 ——
A12: emb_tokens | B12: 60 | C12: tokens | D12: 中文 LINE 訊息平均 20–40 字 → embedding tokens
A13: L4_sys_tokens | B13: 400 | C13: tokens | D13: L4 system prompt（品牌、範圍限制、JSON 格式）
A14: L4_rag_tokens | B14: 1200 | C14: tokens | D14: RAG 3 chunks × 400
A15: L4_hist_tokens | B15: 300 | C15: tokens | D15: 對話歷史 last-N
A16: L4_user_tokens | B16: 60 | C16: tokens | D16: 使用者訊息
A17: L4_out_tokens | B17: 180 | C17: tokens | D17: LINE 回覆偏短
A18: L5_in_tokens | B18: 2760 | C18: tokens | D18: system 600 + RAG 1,500 + history 600 + user 60
A19: L5_out_tokens | B19: 350 | C19: tokens | D19: 較長回覆 / 轉接摘要
A20: —— 模型單價 US$ / 1M tokens ——
A21: P_L4_in | B21: 0.25 | C21: US$/M | D21: Gemini 3.1 Flash-Lite input（2.5 Flash-Lite 2026-10 退役後）
A22: P_L4_out | B22: 1.5 | C22: US$/M | D22: Gemini 3.1 Flash-Lite output
A23: P_L5_in | B23: 1 | C23: US$/M | D23: Claude Haiku 4.5 input
A24: P_L5_out | B24: 5 | C24: US$/M | D24: Claude Haiku 4.5 output
A25: P_emb | B25: 0.02 | C25: US$/M | D25: text-embedding-3-small（gemini-embedding-001 = 0.15）
A26: cache_hit_L5 | B26: 0 | C26: % | D26: L5 prompt cache 命中率（預設 0 = 保守）
A27: cache_discount | B27: 0.9 | C27: % | D27: cache 命中的 input 折扣
A28: —— AWS 增量（免費額度視為已被平台用掉）——
A29: RRU_per_M | B29: 0.125 | C29: US$/M | D29: DynamoDB on-demand read request unit
A30: WRU_per_M | B30: 0.625 | C30: US$/M | D30: DynamoDB on-demand write request unit
A31: Lambda_req_per_M | B31: 0.2 | C31: US$/M | D31: Amplify SSR 實際依 Lambda 計費模型
A32: Lambda_GBs | B32: 1.66667e-05 | C32: US$/GB-s | D32: x86
A33: Lambda_MB | B33: 512 | C33: MB | D33: SSR 函式記憶體
A34: ms_L1 | B34: 150 | C34: ms | D34: 簽章 + 去重 + 查表 + log
A35: ms_L3 | B35: 500 | C35: ms | D35: embedding 呼叫 + 向量比對
A36: ms_L4 | B36: 3000 | C36: ms | D36: 小模型回應等待
A37: ms_L5 | B37: 6000 | C37: ms | D37: 高階模型回應等待
A38: ledger_writes | B38: 4 | C38: WRU | D38: recordUsage = 1 Put + 3 rollup Update（無 orgId 時最小集合）
A39: L1_WRU | B39: 2 | C39: WRU | D39: webhook-logs + dedupe 條件寫入
A40: L1_RRU | B40: 1 | C40: RRU | D40: profile / session 讀取
...

Sheet LayerCost
A1: 每則訊息成本（US$）：inc = 該層新增；cum = 到該層為止累積；blended = Σ hit × cum
A2: 到 L5 的訊息已付 L1+L2+L3+L4；L2 在同一 request 內執行，增量 0
A3: 層 | B3: inc (US$) | C3: cum (US$) | D3: 命中率 | E3: 貢獻 (US$) | F3: inc µ$ | G3: cum µ$ | H3: 說明
A4: L1 Postback / 圖文選單 | B4: =(Inputs!$B$39*Inputs!$B$30+Inputs!$B$40*Inputs!$B$29+Inputs!$B$31)/1000000+Inputs!$B$32*Inputs!$B$33/1024*Inputs!$B$34/1000 | C4: =B4 | D4: =Inputs!$B$5 | E4: =C4*D4 | F4: =B4*1000000 | G4: =C4*1000000 | H4: webhook log + dedupe 寫入、profile 讀取、Lambda 請求費 + 150ms
A5: L2 Keyword / Regex / Rule | B5: =0 | C5: =C4+B5 | D5: =Inputs!$B$6 | E5: =C5*D5 | F5: =B5*1000000 | G5: =C5*1000000 | H5: 同一 request 內的 regex；零增量
A6: L3 Semantic FAQ | B6: =Inputs!$B$12*Inputs!$B$25/1000000+Inputs!$B$29/1000000+Inputs!$B$38*Inputs!$B$30/1000000+Inputs!$B$32*Inputs!$B$33/1024*Inputs!$B$35/1000 | C6: =C5+B6 | D6: =Inputs!$B$7 | E6: =C6*D6 | F6: =B6*1000000 | G6: =C6*1000000 | H6: embedding 呼叫 + 向量查詢 + ledger 4 寫 + 500ms
A7: L4 Cheap LLM (RAG) | B7: =B12+Inputs!$B$38*Inputs!$B$30/1000000+Inputs!$B$32*Inputs!$B$33/1024*Inputs!$B$36/1000 | C7: =C6+B7 | D7: =Inputs!$B$8 | E7: =C7*D7 | F7: =B7*1000000 | G7: =C7*1000000 | H7: LLM-only 單價見 B12 + ledger + 3s
A8: L5 Advanced / Fallback | B8: =B13+Inputs!$B$38*Inputs!$B$30/1000000+Inputs!$B$32*Inputs!$B$33/1024*Inputs!$B$37/1000 | C8: =C7+B8 | D8: =Inputs!$B$9 | E8: =C8*D8 | F8: =B8*1000000 | G8: =C8*1000000 | H8: LLM-only 單價見 B13 + ledger + 6s
A9: blended / 則 (US$) | E9: =SUM(E4:E8) | F9: =E9*1000000 | G9: =E9*Inputs!$B$3 | H9: E = US$，F = µ$（對齊 ledger micro-USD），G = NT$/則
A11: LLM-only 單價（不含 AWS）
A12: unit_A4：L4 每請求 LLM 費 (US$) | B12: =((Inputs!$B$13+Inputs!$B$14+Inputs!$B$15+Inputs!$B$16)*Inputs!$B$21+Inputs!$B$17*Inputs!$B$22)/1000000
A13: unit_A5：L5 每請求 LLM 費 (US$) | B13: =(Inputs!$B$18*Inputs!$B$23*(1-Inputs!$B$26*Inputs!$B$27)+Inputs!$B$19*Inputs!$B$24)/1000000
A14: LLM 佔 blended 比例 | B14: =(D7*B12+D8*(B12+B13))/E9
A15: L5 佔 blended 比例 | B15: =E8/E9

Sheet Scenarios
A1: 月成本情境（US$ 除非標示）；A = 純雲 API，B = 雲 + RunPod 取代 L4，C = 雲 + 自建 GPU 取代 L4
A2: B/C 只把 L4 LLM 移到 RunPod/本機，L1–L3 與 L5 仍在雲端：B/C 總成本 = A 總成本 − 雲端 L4 LLM(N4×unit_A4) + 替代成本
A3: 情境 | B3: msgs/月 | C3: N4 (到達 L4) | D3: N5 (到達 L5) | E3: A 總成本 | F3: A NT$ | G3: LINE 方案+推播 NT$ | H3: B 總成本 | I3: C 總成本 | J3: 最便宜
A4: 現況 | B4: =Inputs!$B$4 | C4: =B4*(Inputs!$B$8+Inputs!$B$9) | D4: =B4*Inputs!$B$9 | E4: =B4*LayerCost!$E$9 | F4: =E4*Inputs!$B$3 | G4: =Inputs!$B$60+MAX(0,Inputs!$B$59-Inputs!$B$61)*Inputs!$B$62 | H4: =E4-C4*LayerCost!$B$12+'TCO-RunPod'!J4 | I4: =E4-C4*LayerCost!$B$12+'TCO-Local'!H14 | J4: =IF(E4<=MIN(H4,I4),"A",IF(H4<=I4,"B","C"))
A5: 1k | B5: 1000 | C5: =B5*(Inputs!$B$8+Inputs!$B$9) | D5: =B5*Inputs!$B$9 | E5: =B5*LayerCost!$E$9 | F5: =E5*Inputs!$B$3 | G5: =Inputs!$B$60+MAX(0,Inputs!$B$59-Inputs!$B$61)*Inputs!$B$62 | H5: =E5-C5*LayerCost!$B$12+'TCO-RunPod'!J5 | I5: =E5-C5*LayerCost!$B$12+'TCO-Local'!H15 | J5: =IF(E5<=MIN(H5,I5),"A",IF(H5<=I5,"B","C"))
A6: 10k | B6: 10000 | C6: =B6*(Inputs!$B$8+Inputs!$B$9) | D6: =B6*Inputs!$B$9 | E6: =B6*LayerCost!$E$9 | F6: =E6*Inputs!$B$3 | G6: =Inputs!$B$60+MAX(0,Inputs!$B$59-Inputs!$B$61)*Inputs!$B$62 | H6: =E6-C6*LayerCost!$B$12+'TCO-RunPod'!J6 | I6: =E6-C6*LayerCost!$B$12+'TCO-Local'!H16 | J6: =IF(E6<=MIN(H6,I6),"A",IF(H6<=I6,"B","C"))
A7: 100k | B7: 100000 | C7: =B7*(Inputs!$B$8+Inputs!$B$9) | D7: =B7*Inputs!$B$9 | E7: =B7*LayerCost!$E$9 | F7: =E7*Inputs!$B$3 | G7: =Inputs!$B$60+MAX(0,Inputs!$B$59-Inputs!$B$61)*Inputs!$B$62 | H7: =E7-C7*LayerCost!$B$12+'TCO-RunPod'!J7 | I7: =E7-C7*LayerCost!$B$12+'TCO-Local'!H17 | J7: =IF(E7<=MIN(H7,I7),"A",IF(H7<=I7,"B","C"))
A8: 1M | B8: 1000000 | C8: =B8*(Inputs!$B$8+Inputs!$B$9) | D8: =B8*Inputs!$B$9 | E8: =B8*LayerCost!$E$9 | F8: =E8*Inputs!$B$3 | G8: =Inputs!$B$60+MAX(0,Inputs!$B$59-Inputs!$B$61)*Inputs!$B$62 | H8: =E8-C8*LayerCost!$B$12+'TCO-RunPod'!J8 | I8: =E8-C8*LayerCost!$B$12+'TCO-Local'!H18 | J8: =IF(E8<=MIN(H8,I8),"A",IF(H8<=I8,"B","C"))
A10: 註：LINE 方案費用與 AI 方案無關（Reply 免費），單獨列出以免混入 A/B/C 比較。

Sheet TCO-RunPod
A1: 方案 B：RunPod Serverless 取代 L4（L3 embedding 與 L5 留雲端）
A2: p_cold = EXP(−λ·idle)：上一請求後 idle_timeout 秒內無新請求即冷啟；flex 與 always-on 並列取 MIN
A3: 情境 | B3: msgs/月 | C3: N4 | D3: λ (req/s) | E3: p_cold | F3: 每請求 US$ | G3: flex 月費 | H3: always-on / worker | I3: 所需 worker | J3: B 總成本 | K3: A 的 L4 LLM 費
A4: =Scenarios!A4 | B4: =Scenarios!B4 | C4: =Scenarios!C4 | D4: =C4/(30*86400) | E4: =EXP(-D4*Inputs!$B$45) | F4: =(Inputs!$B$43+E4*(Inputs!$B$44+Inputs!$B$45))*Inputs!$B$42/3600 | G4: =C4*F4 | H4: =Inputs!$B$42*730*(1-Inputs!$B$46) | I4: =MAX(1,ROUNDUP(C4*Inputs!$B$43/3600/730/Inputs!$B$47,0)) | J4: =MIN(G4,H4*I4) | K4: =C4*LayerCost!$B$12
A5: =Scenarios!A5 | B5: =Scenarios!B5 | C5: =Scenarios!C5 | D5: =C5/(30*86400) | E5: =EXP(-D5*Inputs!$B$45) | F5: =(Inputs!$B$43+E5*(Inputs!$B$44+Inputs!$B$45))*Inputs!$B$42/3600 | G5: =C5*F5 | H5: =Inputs!$B$42*730*(1-Inputs!$B$46) | I5: =MAX(1,ROUNDUP(C5*Inputs!$B$43/3600/730/Inputs!$B$47,0)) | J5: =MIN(G5,H5*I5) | K5: =C5*LayerCost!$B$12
A6: =Scenarios!A6 | B6: =Scenarios!B6 | C6: =Scenarios!C6 | D6: =C6/(30*86400) | E6: =EXP(-D6*Inputs!$B$45) | F6: =(Inputs!$B$43+E6*(Inputs!$B$44+Inputs!$B$45))*Inputs!$B$42/3600 | G6: =C6*F6 | H6: =Inputs!$B$42*730*(1-Inputs!$B$46) | I6: =MAX(1,ROUNDUP(C6*Inputs!$B$43/3600/730/Inputs!$B$47,0)) | J6: =MIN(G6,H6*I6) | K6: =C6*LayerCost!$B$12
A7: =Scenarios!A7 | B7: =Scenarios!B7 | C7: =Scenarios!C7 | D7: =C7/(30*86400) | E7: =EXP(-D7*Inputs!$B$45) | F7: =(Inputs!$B$43+E7*(Inputs!$B$44+Inputs!$B$45))*Inputs!$B$42/3600 | G7: =C7*F7 | H7: =Inputs!$B$42*730*(1-Inputs!$B$46) | I7: =MAX(1,ROUNDUP(C7*Inputs!$B$43/3600/730/Inputs!$B$47,0)) | J7: =MIN(G7,H7*I7) | K7: =C7*LayerCost!$B$12
A8: =Scenarios!A8 | B8: =Scenarios!B8 | C8: =Scenarios!C8 | D8: =C8/(30*86400) | E8: =EXP(-D8*Inputs!$B$45) | F8: =(Inputs!$B$43+E8*(Inputs!$B$44+Inputs!$B$45))*Inputs!$B$42/3600 | G8: =C8*F8 | H8: =Inputs!$B$42*730*(1-Inputs!$B$46) | I8: =MAX(1,ROUNDUP(C8*Inputs!$B$43/3600/730/Inputs!$B$47,0)) | J8: =MIN(G8,H8*I8) | K8: =C8*LayerCost!$B$12
A10: 隱藏成本（未計入）：冷啟 25s 期間使用者無回應（需先 reply 佔位再 push，push 吃 LINE 配額）；模型鏡像儲存；無 SLA。
A11: 理論下限（100% warm）= t_active × $/s；與雲端 unit_A4 比：
A12: warm 每請求 US$ | B12: =Inputs!$B$43*Inputs!$B$42/3600
A13: warm / unit_A4（<1 才可能省） | B13: =B12/LayerCost!$B$12

Sheet TCO-Local
A1: 方案 C：自建 RTX 5090 級主機取代 L4（單機、無 HA；故障期間 L4 全部 fallback 到雲端）
A3: 固定成本項 (NT$/月) | B3: 值 | C3: 公式
A4: 設備折舊 | B4: =Inputs!$B$49/(Inputs!$B$50*12) | C4: box_cost / (年 × 12)
A5: 待機電費 | B5: =Inputs!$B$51/1000*730*Inputs!$B$53 | C5: idle_W × 730h × 電價
A6: 維護工時 | B6: =Inputs!$B$54*Inputs!$B$55 | C6: maint_hr × 時薪（最大單項）
A7: UPS / 備援折舊 | B7: =Inputs!$B$56/(Inputs!$B$50*12)
A8: 故障 / 升級準備金 | B8: =Inputs!$B$49*Inputs!$B$57/12 | C8: box_cost × 年率 / 12
A9: 固定成本合計 NT$/月 | B9: =SUM(B4:B8)
A10: 固定成本合計 US$/月 | B10: =B9/Inputs!$B$3
A11: 維護工時占比 | B11: =B6/B9
A13: 情境 | B13: msgs/月 | C13: N4 | D13: GPU 負載小時 | E13: 利用率 | F13: 負載電費 NT$ | G13: 所需 GPU 數 | H13: C 總成本 US$ | I13: A 的 L4 LLM 費
A14: =Scenarios!A4 | B14: =Scenarios!B4 | C14: =Scenarios!C4 | D14: =C14*Inputs!$B$43/3600 | E14: =D14/730 | F14: =(Inputs!$B$52-Inputs!$B$51)/1000*D14*Inputs!$B$53 | G14: =MAX(1,ROUNDUP(E14/Inputs!$B$47,0)) | H14: =($B$9*G14+F14)/Inputs!$B$3 | I14: =C14*LayerCost!$B$12
A15: =Scenarios!A5 | B15: =Scenarios!B5 | C15: =Scenarios!C5 | D15: =C15*Inputs!$B$43/3600 | E15: =D15/730 | F15: =(Inputs!$B$52-Inputs!$B$51)/1000*D15*Inputs!$B$53 | G15: =MAX(1,ROUNDUP(E15/Inputs!$B$47,0)) | H15: =($B$9*G15+F15)/Inputs!$B$3 | I15: =C15*LayerCost!$B$12
A16: =Scenarios!A6 | B16: =Scenarios!B6 | C16: =Scenarios!C6 | D16: =C16*Inputs!$B$43/3600 | E16: =D16/730 | F16: =(Inputs!$B$52-Inputs!$B$51)/1000*D16*Inputs!$B$53 | G16: =MAX(1,ROUNDUP(E16/Inputs!$B$47,0)) | H16: =($B$9*G16+F16)/Inputs!$B$3 | I16: =C16*LayerCost!$B$12
A17: =Scenarios!A7 | B17: =Scenarios!B7 | C17: =Scenarios!C7 | D17: =C17*Inputs!$B$43/3600 | E17: =D17/730 | F17: =(Inputs!$B$52-Inputs!$B$51)/1000*D17*Inputs!$B$53 | G17: =MAX(1,ROUNDUP(E17/Inputs!$B$47,0)) | H17: =($B$9*G17+F17)/Inputs!$B$3 | I17: =C17*LayerCost!$B$12
A18: =Scenarios!A8 | B18: =Scenarios!B8 | C18: =Scenarios!C8 | D18: =C18*Inputs!$B$43/3600 | E18: =D18/730 | F18: =(Inputs!$B$52-Inputs!$B$51)/1000*D18*Inputs!$B$53 | G18: =MAX(1,ROUNDUP(E18/Inputs!$B$47,0)) | H18: =($B$9*G18+F18)/Inputs!$B$3 | I18: =C18*LayerCost!$B$12
A20: 可用性：單機無 HA、家用電/網路中斷不在 UPS 涵蓋、折舊期內 GPU 跌價不退；必須同時維護雲端 fallback（gateway provider 抽象是唯一前提）。

Sheet Breakeven
A1: 損益兩平（閉式解，不需 goal seek）
A3: unit_A4：雲端 L4 每請求 LLM 費 US$ | B3: =LayerCost!$B$12
A4: share4 = hit_L4 + hit_L5 | B4: =Inputs!$B$8+Inputs!$B$9
A5: 自建每請求負載電費 US$ | B5: =(Inputs!$B$52-Inputs!$B$51)/1000*Inputs!$B$43/3600*Inputs!$B$53/Inputs!$B$3
A6: C 勝 A：L4 請求數/月 | B6: ='TCO-Local'!$B$10/(B3-B5)
A7: C 勝 A：msgs/月 | B7: =B6/B4
A8: C 勝 A 時單卡利用率 | B8: =B6*Inputs!$B$43/3600/730
A9: B(always-on) 勝 A：L4 請求數/月 | B9: =Inputs!$B$42*730*(1-Inputs!$B$46)/B3
A10: B(always-on) 勝 A：msgs/月 | B10: =B9/B4
A11: B flex 勝 A？ | B11: =IF('TCO-RunPod'!$B$12<B3,"僅在 100% warm 才可能","永不")
A14: 2-D：C 勝 A 的 msgs/月 — 列 = L4 模型單價（in/out US$/M），欄 = tokens 倍率
A15: L4 模型 | B15: in | C15: out | D15: ×1 | E15: ×2 | F15: ×3
A16: Gemini 3.1 Flash-Lite | B16: 0.25 | C16: 1.5 | D16: ='TCO-Local'!$B$10/(((Inputs!$B$13+Inputs!$B$14+Inputs!$B$15+Inputs!$B$16)*$B16+Inputs!$B$17*$C16)/1000000*1-$B$5)/$B$4 | E16: ='TCO-Local'!$B$10/(((Inputs!$B$13+Inputs!$B$14+Inputs!$B$15+Inputs!$B$16)*$B16+Inputs!$B$17*$C16)/1000000*2-$B$5)/$B$4 | F16: ='TCO-Local'!$B$10/(((Inputs!$B$13+Inputs!$B$14+Inputs!$B$15+Inputs!$B$16)*$B16+Inputs!$B$17*$C16)/1000000*3-$B$5)/$B$4
A17: GPT-5.4 nano | B17: 0.2 | C17: 1.25 | D17: ='TCO-Local'!$B$10/(((Inputs!$B$13+Inputs!$B$14+Inputs!$B$15+Inputs!$B$16)*$B17+Inputs!$B$17*$C17)/1000000*1-$B$5)/$B$4 | E17: ='TCO-Local'!$B$10/(((Inputs!$B$13+Inputs!$B$14+Inputs!$B$15+Inputs!$B$16)*$B17+Inputs!$B$17*$C17)/1000000*2-$B$5)/$B$4 | F17: ='TCO-Local'!$B$10/(((Inputs!$B$13+Inputs!$B$14+Inputs!$B$15+Inputs!$B$16)*$B17+Inputs!$B$17*$C17)/1000000*3-$B$5)/$B$4
A18: GPT-5.4 mini | B18: 0.75 | C18: 4.5 | D18: ='TCO-Local'!$B$10/(((Inputs!$B$13+Inputs!$B$14+Inputs!$B$15+Inputs!$B$16)*$B18+Inputs!$B$17*$C18)/1000000*1-$B$5)/$B$4 | E18: ='TCO-Local'!$B$10/(((Inputs!$B$13+Inputs!$B$14+Inputs!$B$15+Inputs!$B$16)*$B18+Inputs!$B$17*$C18)/1000000*2-$B$5)/$B$4 | F18: ='TCO-Local'!$B$10/(((Inputs!$B$13+Inputs!$B$14+Inputs!$B$15+Inputs!$B$16)*$B18+Inputs!$B$17*$C18)/1000000*3-$B$5)/$B$4
A19: Claude Haiku 4.5 | B19: 1 | C19: 5 | D19: ='TCO-Local'!$B$10/(((Inputs!$B$13+Inputs!$B$14+Inputs!$B$15+Inputs!$B$16)*$B19+Inputs!$B$17*$C19)/1000000*1-$B$5)/$B$4 | E19: ='TCO-Local'!$B$10/(((Inputs!$B$13+Inputs!$B$14+Inputs!$B$15+Inputs!$B$16)*$B19+Inputs!$B$17*$C19)/1000000*2-$B$5)/$B$4 | F19: ='TCO-Local'!$B$10/(((Inputs!$B$13+Inputs!$B$14+Inputs!$B$15+Inputs!$B$16)*$B19+Inputs!$B$17*$C19)/1000000*3-$B$5)/$B$4
A21: 讀法：格內數字 = 每月訊息量門檻；低於此值留在雲端 A。

Sheet Sensitivity
A1: 敏感度分析
A3: 表 1：命中率組合 → blended µ$/則 與 100k msgs 月費 US$
A4: 組合 | B4: L1 | C4: L2 | D4: L3 | E4: L4 | F4: L5 | G4: blended µ$ | H4: 100k 月費 US$
A5: 預設 | B5: =Inputs!$B$5 | C5: =Inputs!$B$6 | D5: =Inputs!$B$7 | E5: =Inputs!$B$8 | F5: =Inputs!$B$9 | G5: =(B5*LayerCost!$C$4+C5*LayerCost!$C$5+D5*LayerCost!$C$6+E5*LayerCost!$C$7+F5*LayerCost!$C$8)*1000000 | H5: =G5/1000000*100000
A6: 平均 20% | B6: 0.2 | C6: 0.2 | D6: 0.2 | E6: 0.2 | F6: 0.2 | G6: =(B6*LayerCost!$C$4+C6*LayerCost!$C$5+D6*LayerCost!$C$6+E6*LayerCost!$C$7+F6*LayerCost!$C$8)*1000000 | H6: =G6/1000000*100000
A7: 悲觀 (規則層弱) | B7: 0.1 | C7: 0.1 | D7: 0.2 | E7: 0.4 | F7: 0.2 | G7: =(B7*LayerCost!$C$4+C7*LayerCost!$C$5+D7*LayerCost!$C$6+E7*LayerCost!$C$7+F7*LayerCost!$C$8)*1000000 | H7: =G7/1000000*100000
A8: 樂觀 (規則層強) | B8: 0.4 | C8: 0.3 | D8: 0.2 | E8: 0.08 | F8: 0.02 | G8: =(B8*LayerCost!$C$4+C8*LayerCost!$C$5+D8*LayerCost!$C$6+E8*LayerCost!$C$7+F8*LayerCost!$C$8)*1000000 | H8: =G8/1000000*100000
A11: 表 2：單一 knob 變動 → blended µ$/則（其餘維持 Inputs）
A12: Knob | B12: −50% | C12: 預設 | D12: +100% | E12: 說明
A13: L5 命中率 (5% → 2.5% / 10%) | B13: =(Inputs!$B$5*LayerCost!$C$4+Inputs!$B$6*LayerCost!$C$5+Inputs!$B$7*LayerCost!$C$6+(Inputs!$B$8+Inputs!$B$9-Inputs!$B$9*0.5)*(LayerCost!$C$6+(((Inputs!$B$13+Inputs!$B$14+Inputs!$B$15+Inputs!$B$16)*Inputs!$B$21+Inputs!$B$17*Inputs!$B$22)*1/1000000+Inputs!$B$38*Inputs!$B$30/1000000+Inputs!$B$32*Inputs!$B$33/1024*Inputs!$B$36/1000))+Inputs!$B$9*0.5*(LayerCost!$C$6+(((Inputs!$B$13+Inputs!$B$14+Inputs!$B$15+Inputs!$B$16)*Inputs!$B$21+Inputs!$B$17*Inputs!$B$22)*1/1000000+Inputs!$B$38*Inputs!$B$30/1000000+Inputs!$B$32*Inputs!$B$33/1024*Inputs!$B$36/1000)+((Inputs!$B$18*Inputs!$B$23*(1-Inputs!$B$26*Inputs!$B$27)+Inputs!$B$19*Inputs!$B$24)*1/1000000+Inputs!$B$38*Inputs!$B$30/1000000+Inputs!$B$32*Inputs!$B$33/1024*Inputs!$B$37/1000)))*1000000 | C13: =(Inputs!$B$5*LayerCost!$C$4+Inputs!$B$6*LayerCost!$C$5+Inputs!$B$7*LayerCost!$C$6+(Inputs!$B$8+Inputs!$B$9-Inputs!$B$9)*(LayerCost!$C$6+(((Inputs!$B$13+Inputs!$B$14+Inputs!$B$15+Inputs!$B$16)*Inputs!$B$21+Inputs!$B$17*Inputs!$B$22)*1/1000000+Inputs!$B$38*Inputs!$B$30/1000000+Inputs!$B$32*Inputs!$B$33/1024*Inputs!$B$36/1000))+Inputs!$B$9*(LayerCost!$C$6+(((Inputs!$B$13+Inputs!$B$14+Inputs!$B$15+Inputs!$B$16)*Inputs!$B$21+Inputs!$B$17*Inputs!$B$22)*1/1000000+Inputs!$B$38*Inputs!$B$30/1000000+Inputs!$B$32*Inputs!$B$33/1024*Inputs!$B$36/1000)+((Inputs!$B$18*Inputs!$B$23*(1-Inputs!$B$26*Inputs!$B$27)+Inputs!$B$19*Inputs!$B$24)*1/1000000+Inputs!$B$38*Inputs!$B$30/1000000+Inputs!$B$32*Inputs!$B$33/1024*Inputs!$B$37/1000)))*1000000 | D13: =(Inputs!$B$5*LayerCost!$C$4+Inputs!$B$6*LayerCost!$C$5+Inputs!$B$7*LayerCost!$C$6+(Inputs!$B$8+Inputs!$B$9-Inputs!$B$9*2)*(LayerCost!$C$6+(((Inputs!$B$13+Inputs!$B$14+Inputs!$B$15+Inputs!$B$16)*Inputs!$B$21+Inputs!$B$17*Inputs!$B$22)*1/1000000+Inputs!$B$38*Inputs!$B$30/1000000+Inputs!$B$32*Inputs!$B$33/1024*Inputs!$B$36/1000))+Inputs!$B$9*2*(LayerCost!$C$6+(((Inputs!$B$13+Inputs!$B$14+Inputs!$B$15+Inputs!$B$16)*Inputs!$B$21+Inputs!$B$17*Inputs!$B$22)*1/1000000+Inputs!$B$38*Inputs!$B$30/1000000+Inputs!$B$32*Inputs!$B$33/1024*Inputs!$B$36/1000)+((Inputs!$B$18*Inputs!$B$23*(1-Inputs!$B$26*Inputs!$B$27)+Inputs!$B$19*Inputs!$B$24)*1/1000000+Inputs!$B$38*Inputs!$B$30/1000000+Inputs!$B$32*Inputs!$B$33/1024*Inputs!$B$37/1000)))*1000000 | E13: L4 吸收差額，總和仍 100%
A14: L4 tokens/則 | B14: =(Inputs!$B$5*LayerCost!$C$4+Inputs!$B$6*LayerCost!$C$5+Inputs!$B$7*LayerCost!$C$6+(Inputs!$B$8+Inputs!$B$9-Inputs!$B$9)*(LayerCost!$C$6+(((Inputs!$B$13+Inputs!$B$14+Inputs!$B$15+Inputs!$B$16)*Inputs!$B$21+Inputs!$B$17*Inputs!$B$22)*0.5/1000000+Inputs!$B$38*Inputs!$B$30/1000000+Inputs!$B$32*Inputs!$B$33/1024*Inputs!$B$36/1000))+Inputs!$B$9*(LayerCost!$C$6+(((Inputs!$B$13+Inputs!$B$14+Inputs!$B$15+Inputs!$B$16)*Inputs!$B$21+Inputs!$B$17*Inputs!$B$22)*0.5/1000000+Inputs!$B$38*Inputs!$B$30/1000000+Inputs!$B$32*Inputs!$B$33/1024*Inputs!$B$36/1000)+((Inputs!$B$18*Inputs!$B$23*(1-Inputs!$B$26*Inputs!$B$27)+Inputs!$B$19*Inputs!$B$24)*1/1000000+Inputs!$B$38*Inputs!$B$30/1000000+Inputs!$B$32*Inputs!$B$33/1024*Inputs!$B$37/1000)))*1000000 | C14: =(Inputs!$B$5*LayerCost!$C$4+Inputs!$B$6*LayerCost!$C$5+Inputs!$B$7*LayerCost!$C$6+(Inputs!$B$8+Inputs!$B$9-Inputs!$B$9)*(LayerCost!$C$6+(((Inputs!$B$13+Inputs!$B$14+Inputs!$B$15+Inputs!$B$16)*Inputs!$B$21+Inputs!$B$17*Inputs!$B$22)*1/1000000+Inputs!$B$38*Inputs!$B$30/1000000+Inputs!$B$32*Inputs!$B$33/1024*Inputs!$B$36/1000))+Inputs!$B$9*(LayerCost!$C$6+(((Inputs!$B$13+Inputs!$B$14+Inputs!$B$15+Inputs!$B$16)*Inputs!$B$21+Inputs!$B$17*Inputs!$B$22)*1/1000000+Inputs!$B$38*Inputs!$B$30/1000000+Inputs!$B$32*Inputs!$B$33/1024*Inputs!$B$36/1000)+((Inputs!$B$18*Inputs!$B$23*(1-Inputs!$B$26*Inputs!$B$27)+Inputs!$B$19*Inputs!$B$24)*1/1000000+Inputs!$B$38*Inputs!$B$30/1000000+Inputs!$B$32*Inputs!$B$33/1024*Inputs!$B$37/1000)))*1000000 | D14: =(Inputs!$B$5*LayerCost!$C$4+Inputs!$B$6*LayerCost!$C$5+Inputs!$B$7*LayerCost!$C$6+(Inputs!$B$8+Inputs!$B$9-Inputs!$B$9)*(LayerCost!$C$6+(((Inputs!$B$13+Inputs!$B$14+Inputs!$B$15+Inputs!$B$16)*Inputs!$B$21+Inputs!$B$17*Inputs!$B$22)*2/1000000+Inputs!$B$38*Inputs!$B$30/1000000+Inputs!$B$32*Inputs!$B$33/1024*Inputs!$B$36/1000))+Inputs!$B$9*(LayerCost!$C$6+(((Inputs!$B$13+Inputs!$B$14+Inputs!$B$15+Inputs!$B$16)*Inputs!$B$21+Inputs!$B$17*Inputs!$B$22)*2/1000000+Inputs!$B$38*Inputs!$B$30/1000000+Inputs!$B$32*Inputs!$B$33/1024*Inputs!$B$36/1000)+((Inputs!$B$18*Inputs!$B$23*(1-Inputs!$B$26*Inputs!$B$27)+Inputs!$B$19*Inputs!$B$24)*1/1000000+Inputs!$B$38*Inputs!$B$30/1000000+Inputs!$B$32*Inputs!$B$33/1024*Inputs!$B$37/1000)))*1000000 | E14: RAG chunk 數、歷史長度
A15: L5 tokens/則 | B15: =(Inputs!$B$5*LayerCost!$C$4+Inputs!$B$6*LayerCost!$C$5+Inputs!$B$7*LayerCost!$C$6+(Inputs!$B$8+Inputs!$B$9-Inputs!$B$9)*(LayerCost!$C$6+(((Inputs!$B$13+Inputs!$B$14+Inputs!$B$15+Inputs!$B$16)*Inputs!$B$21+Inputs!$B$17*Inputs!$B$22)*1/1000000+Inputs!$B$38*Inputs!$B$30/1000000+Inputs!$B$32*Inputs!$B$33/1024*Inputs!$B$36/1000))+Inputs!$B$9*(LayerCost!$C$6+(((Inputs!$B$13+Inputs!$B$14+Inputs!$B$15+Inputs!$B$16)*Inputs!$B$21+Inputs!$B$17*Inputs!$B$22)*1/1000000+Inputs!$B$38*Inputs!$B$30/1000000+Inputs!$B$32*Inputs!$B$33/1024*Inputs!$B$36/1000)+((Inputs!$B$18*Inputs!$B$23*(1-Inputs!$B$26*Inputs!$B$27)+Inputs!$B$19*Inputs!$B$24)*0.5/1000000+Inputs!$B$38*Inputs!$B$30/1000000+Inputs!$B$32*Inputs!$B$33/1024*Inputs!$B$37/1000)))*1000000 | C15: =(Inputs!$B$5*LayerCost!$C$4+Inputs!$B$6*LayerCost!$C$5+Inputs!$B$7*LayerCost!$C$6+(Inputs!$B$8+Inputs!$B$9-Inputs!$B$9)*(LayerCost!$C$6+(((Inputs!$B$13+Inputs!$B$14+Inputs!$B$15+Inputs!$B$16)*Inputs!$B$21+Inputs!$B$17*Inputs!$B$22)*1/1000000+Inputs!$B$38*Inputs!$B$30/1000000+Inputs!$B$32*Inputs!$B$33/1024*Inputs!$B$36/1000))+Inputs!$B$9*(LayerCost!$C$6+(((Inputs!$B$13+Inputs!$B$14+Inputs!$B$15+Inputs!$B$16)*Inputs!$B$21+Inputs!$B$17*Inputs!$B$22)*1/1000000+Inputs!$B$38*Inputs!$B$30/1000000+Inputs!$B$32*Inputs!$B$33/1024*Inputs!$B$36/1000)+((Inputs!$B$18*Inputs!$B$23*(1-Inputs!$B$26*Inputs!$B$27)+Inputs!$B$19*Inputs!$B$24)*1/1000000+Inputs!$B$38*Inputs!$B$30/1000000+Inputs!$B$32*Inputs!$B$33/1024*Inputs!$B$37/1000)))*1000000 | D15: =(Inputs!$B$5*LayerCost!$C$4+Inputs!$B$6*LayerCost!$C$5+Inputs!$B$7*LayerCost!$C$6+(Inputs!$B$8+Inputs!$B$9-Inputs!$B$9)*(LayerCost!$C$6+(((Inputs!$B$13+Inputs!$B$14+Inputs!$B$15+Inputs!$B$16)*Inputs!$B$21+Inputs!$B$17*Inputs!$B$22)*1/1000000+Inputs!$B$38*Inputs!$B$30/1000000+Inputs!$B$32*Inputs!$B$33/1024*Inputs!$B$36/1000))+Inputs!$B$9*(LayerCost!$C$6+(((Inputs!$B$13+Inputs!$B$14+Inputs!$B$15+Inputs!$B$16)*Inputs!$B$21+Inputs!$B$17*Inputs!$B$22)*1/1000000+Inputs!$B$38*Inputs!$B$30/1000000+Inputs!$B$32*Inputs!$B$33/1024*Inputs!$B$36/1000)+((Inputs!$B$18*Inputs!$B$23*(1-Inputs!$B$26*Inputs!$B$27)+Inputs!$B$19*Inputs!$B$24)*2/1000000+Inputs!$B$38*Inputs!$B$30/1000000+Inputs!$B$32*Inputs!$B$33/1024*Inputs!$B$37/1000)))*1000000
A16: L4 單價 (Flash-Lite → nano / mini) | B16: =(Inputs!$B$5*LayerCost!$C$4+Inputs!$B$6*LayerCost!$C$5+Inputs!$B$7*LayerCost!$C$6+(Inputs!$B$8+Inputs!$B$9-Inputs!$B$9)*(LayerCost!$C$6+(((Inputs!$B$13+Inputs!$B$14+Inputs!$B$15+Inputs!$B$16)*0.20+Inputs!$B$17*1.25)*1/1000000+Inputs!$B$38*Inputs!$B$30/1000000+Inputs!$B$32*Inputs!$B$33/1024*Inputs!$B$36/1000))+Inputs!$B$9*(LayerCost!$C$6+(((Inputs!$B$13+Inputs!$B$14+Inputs!$B$15+Inputs!$B$16)*0.20+Inputs!$B$17*1.25)*1/1000000+Inputs!$B$38*Inputs!$B$30/1000000+Inputs!$B$32*Inputs!$B$33/1024*Inputs!$B$36/1000)+((Inputs!$B$18*Inputs!$B$23*(1-Inputs!$B$26*Inputs!$B$27)+Inputs!$B$19*Inputs!$B$24)*1/1000000+Inputs!$B$38*Inputs!$B$30/1000000+Inputs!$B$32*Inputs!$B$33/1024*Inputs!$B$37/1000)))*1000000 | C16: =(Inputs!$B$5*LayerCost!$C$4+Inputs!$B$6*LayerCost!$C$5+Inputs!$B$7*LayerCost!$C$6+(Inputs!$B$8+Inputs!$B$9-Inputs!$B$9)*(LayerCost!$C$6+(((Inputs!$B$13+Inputs!$B$14+Inputs!$B$15+Inputs!$B$16)*Inputs!$B$21+Inputs!$B$17*Inputs!$B$22)*1/1000000+Inputs!$B$38*Inputs!$B$30/1000000+Inputs!$B$32*Inputs!$B$33/1024*Inputs!$B$36/1000))+Inputs!$B$9*(LayerCost!$C$6+(((Inputs!$B$13+Inputs!$B$14+Inputs!$B$15+Inputs!$B$16)*Inputs!$B$21+Inputs!$B$17*Inputs!$B$22)*1/1000000+Inputs!$B$38*Inputs!$B$30/1000000+Inputs!$B$32*Inputs!$B$33/1024*Inputs!$B$36/1000)+((Inputs!$B$18*Inputs!$B$23*(1-Inputs!$B$26*Inputs!$B$27)+Inputs!$B$19*Inputs!$B$24)*1/1000000+Inputs!$B$38*Inputs!$B$30/1000000+Inputs!$B$32*Inputs!$B$33/1024*Inputs!$B$37/1000)))*1000000 | D16: =(Inputs!$B$5*LayerCost!$C$4+Inputs!$B$6*LayerCost!$C$5+Inputs!$B$7*LayerCost!$C$6+(Inputs!$B$8+Inputs!$B$9-Inputs!$B$9)*(LayerCost!$C$6+(((Inputs!$B$13+Inputs!$B$14+Inputs!$B$15+Inputs!$B$16)*0.75+Inputs!$B$17*4.50)*1/1000000+Inputs!$B$38*Inputs!$B$30/1000000+Inputs!$B$32*Inputs!$B$33/1024*Inputs!$B$36/1000))+Inputs!$B$9*(LayerCost!$C$6+(((Inputs!$B$13+Inputs!$B$14+Inputs!$B$15+Inputs!$B$16)*0.75+Inputs!$B$17*4.50)*1/1000000+Inputs!$B$38*Inputs!$B$30/1000000+Inputs!$B$32*Inputs!$B$33/1024*Inputs!$B$36/1000)+((Inputs!$B$18*Inputs!$B$23*(1-Inputs!$B$26*Inputs!$B$27)+Inputs!$B$19*Inputs!$B$24)*1/1000000+Inputs!$B$38*Inputs!$B$30/1000000+Inputs!$B$32*Inputs!$B$33/1024*Inputs!$B$37/1000)))*1000000 | E16: 欄位為 nano / 預設 / mini
A17: L5 prompt cache 命中 (0 → 50% / 90%) | B17: =(Inputs!$B$5*LayerCost!$C$4+Inputs!$B$6*LayerCost!$C$5+Inputs!$B$7*LayerCost!$C$6+(Inputs!$B$8+Inputs!$B$9-Inputs!$B$9)*(LayerCost!$C$6+(((Inputs!$B$13+Inputs!$B$14+Inputs!$B$15+Inputs!$B$16)*Inputs!$B$21+Inputs!$B$17*Inputs!$B$22)*1/1000000+Inputs!$B$38*Inputs!$B$30/1000000+Inputs!$B$32*Inputs!$B$33/1024*Inputs!$B$36/1000))+Inputs!$B$9*(LayerCost!$C$6+(((Inputs!$B$13+Inputs!$B$14+Inputs!$B$15+Inputs!$B$16)*Inputs!$B$21+Inputs!$B$17*Inputs!$B$22)*1/1000000+Inputs!$B$38*Inputs!$B$30/1000000+Inputs!$B$32*Inputs!$B$33/1024*Inputs!$B$36/1000)+((Inputs!$B$18*Inputs!$B$23*(1-0.5*Inputs!$B$27)+Inputs!$B$19*Inputs!$B$24)*1/1000000+Inputs!$B$38*Inputs!$B$30/1000000+Inputs!$B$32*Inputs!$B$33/1024*Inputs!$B$37/1000)))*1000000 | C17: =(Inputs!$B$5*LayerCost!$C$4+Inputs!$B$6*LayerCost!$C$5+Inputs!$B$7*LayerCost!$C$6+(Inputs!$B$8+Inputs!$B$9-Inputs!$B$9)*(LayerCost!$C$6+(((Inputs!$B$13+Inputs!$B$14+Inputs!$B$15+Inputs!$B$16)*Inputs!$B$21+Inputs!$B$17*Inputs!$B$22)*1/1000000+Inputs!$B$38*Inputs!$B$30/1000000+Inputs!$B$32*Inputs!$B$33/1024*Inputs!$B$36/1000))+Inputs!$B$9*(LayerCost!$C$6+(((Inputs!$B$13+Inputs!$B$14+Inputs!$B$15+Inputs!$B$16)*Inputs!$B$21+Inputs!$B$17*Inputs!$B$22)*1/1000000+Inputs!$B$38*Inputs!$B$30/1000000+Inputs!$B$32*Inputs!$B$33/1024*Inputs!$B$36/1000)+((Inputs!$B$18*Inputs!$B$23*(1-Inputs!$B$26*Inputs!$B$27)+Inputs!$B$19*Inputs!$B$24)*1/1000000+Inputs!$B$38*Inputs!$B$30/1000000+Inputs!$B$32*Inputs!$B$33/1024*Inputs!$B$37/1000)))*1000000 | D17: =(Inputs!$B$5*LayerCost!$C$4+Inputs!$B$6*LayerCost!$C$5+Inputs!$B$7*LayerCost!$C$6+(Inputs!$B$8+Inputs!$B$9-Inputs!$B$9)*(LayerCost!$C$6+(((Inputs!$B$13+Inputs!$B$14+Inputs!$B$15+Inputs!$B$16)*Inputs!$B$21+Inputs!$B$17*Inputs!$B$22)*1/1000000+Inputs!$B$38*Inputs!$B$30/1000000+Inputs!$B$32*Inputs!$B$33/1024*Inputs!$B$36/1000))+Inputs!$B$9*(LayerCost!$C$6+(((Inputs!$B$13+Inputs!$B$14+Inputs!$B$15+Inputs!$B$16)*Inputs!$B$21+Inputs!$B$17*Inputs!$B$22)*1/1000000+Inputs!$B$38*Inputs!$B$30/1000000+Inputs!$B$32*Inputs!$B$33/1024*Inputs!$B$36/1000)+((Inputs!$B$18*Inputs!$B$23*(1-0.9*Inputs!$B$27)+Inputs!$B$19*Inputs!$B$24)*1/1000000+Inputs!$B$38*Inputs!$B$30/1000000+Inputs!$B$32*Inputs!$B$33/1024*Inputs!$B$37/1000)))*1000000 | E17: cache 折扣依 Inputs
A20: 表 3：自建 (C) 損益兩平 msgs/月 對 knob 的敏感度
A21: Knob | B21: 低 | C21: 預設 | D21: 高 | E21: 說明
A22: 維護工時 hr/月 (0 / 4 / 8) | B22: =(Inputs!$B$49/(Inputs!$B$50*12)+Inputs!$B$51/1000*730*Inputs!$B$53+0*Inputs!$B$55+Inputs!$B$56/(Inputs!$B$50*12)+Inputs!$B$49*Inputs!$B$57/12)/Inputs!$B$3/(LayerCost!$B$12-((Inputs!$B$52-Inputs!$B$51)/1000*Inputs!$B$43/3600*Inputs!$B$53/Inputs!$B$3))/Breakeven!$B$4 | C22: =(Inputs!$B$49/(Inputs!$B$50*12)+Inputs!$B$51/1000*730*Inputs!$B$53+Inputs!$B$54*Inputs!$B$55+Inputs!$B$56/(Inputs!$B$50*12)+Inputs!$B$49*Inputs!$B$57/12)/Inputs!$B$3/(LayerCost!$B$12-((Inputs!$B$52-Inputs!$B$51)/1000*Inputs!$B$43/3600*Inputs!$B$53/Inputs!$B$3))/Breakeven!$B$4 | D22: =(Inputs!$B$49/(Inputs!$B$50*12)+Inputs!$B$51/1000*730*Inputs!$B$53+Inputs!$B$54*2*Inputs!$B$55+Inputs!$B$56/(Inputs!$B$50*12)+Inputs!$B$49*Inputs!$B$57/12)/Inputs!$B$3/(LayerCost!$B$12-((Inputs!$B$52-Inputs!$B$51)/1000*Inputs!$B$43/3600*Inputs!$B$53/Inputs!$B$3))/Breakeven!$B$4 | E22: 設 0 是自欺；仍是最大槓桿
A23: 電價 NT$/度 (2.25 / 4.5 / 9.39) | B23: =(Inputs!$B$49/(Inputs!$B$50*12)+Inputs!$B$51/1000*730*2.25+Inputs!$B$54*Inputs!$B$55+Inputs!$B$56/(Inputs!$B$50*12)+Inputs!$B$49*Inputs!$B$57/12)/Inputs!$B$3/(LayerCost!$B$12-((Inputs!$B$52-Inputs!$B$51)/1000*Inputs!$B$43/3600*2.25/Inputs!$B$3))/Breakeven!$B$4 | C23: =(Inputs!$B$49/(Inputs!$B$50*12)+Inputs!$B$51/1000*730*Inputs!$B$53+Inputs!$B$54*Inputs!$B$55+Inputs!$B$56/(Inputs!$B$50*12)+Inputs!$B$49*Inputs!$B$57/12)/Inputs!$B$3/(LayerCost!$B$12-((Inputs!$B$52-Inputs!$B$51)/1000*Inputs!$B$43/3600*Inputs!$B$53/Inputs!$B$3))/Breakeven!$B$4 | D23: =(Inputs!$B$49/(Inputs!$B$50*12)+Inputs!$B$51/1000*730*9.39+Inputs!$B$54*Inputs!$B$55+Inputs!$B$56/(Inputs!$B$50*12)+Inputs!$B$49*Inputs!$B$57/12)/Inputs!$B$3/(LayerCost!$B$12-((Inputs!$B$52-Inputs!$B$51)/1000*Inputs!$B$43/3600*9.39/Inputs!$B$3))/Breakeven!$B$4 | E23: 影響 < 3%
A24: 整機成本 (×0.5 / ×1 / ×2) | B24: =(Inputs!$B$49*0.5/(Inputs!$B$50*12)+Inputs!$B$51/1000*730*Inputs!$B$53+Inputs!$B$54*Inputs!$B$55+Inputs!$B$56/(Inputs!$B$50*12)+Inputs!$B$49*0.5*Inputs!$B$57/12)/Inputs!$B$3/(LayerCost!$B$12-((Inputs!$B$52-Inputs!$B$51)/1000*Inputs!$B$43/3600*Inputs!$B$53/Inputs!$B$3))/Breakeven!$B$4 | C24: =(Inputs!$B$49/(Inputs!$B$50*12)+Inputs!$B$51/1000*730*Inputs!$B$53+Inputs!$B$54*Inputs!$B$55+Inputs!$B$56/(Inputs!$B$50*12)+Inputs!$B$49*Inputs!$B$57/12)/Inputs!$B$3/(LayerCost!$B$12-((Inputs!$B$52-Inputs!$B$51)/1000*Inputs!$B$43/3600*Inputs!$B$53/Inputs!$B$3))/Breakeven!$B$4 | D24: =(Inputs!$B$49*2/(Inputs!$B$50*12)+Inputs!$B$51/1000*730*Inputs!$B$53+Inputs!$B$54*Inputs!$B$55+Inputs!$B$56/(Inputs!$B$50*12)+Inputs!$B$49*2*Inputs!$B$57/12)/Inputs!$B$3/(LayerCost!$B$12-((Inputs!$B$52-Inputs!$B$51)/1000*Inputs!$B$43/3600*Inputs!$B$53/Inputs!$B$3))/Breakeven!$B$4
A25: t_active 秒 (1 / 2.5 / 5) | B25: =(Inputs!$B$49/(Inputs!$B$50*12)+Inputs!$B$51/1000*730*Inputs!$B$53+Inputs!$B$54*Inputs!$B$55+Inputs!$B$56/(Inputs!$B$50*12)+Inputs!$B$49*Inputs!$B$57/12)/Inputs!$B$3/(LayerCost!$B$12-((Inputs!$B$52-Inputs!$B$51)/1000*1/3600*Inputs!$B$53/Inputs!$B$3))/Breakeven!$B$4 | C25: =(Inputs!$B$49/(Inputs!$B$50*12)+Inputs!$B$51/1000*730*Inputs!$B$53+Inputs!$B$54*Inputs!$B$55+Inputs!$B$56/(Inputs!$B$50*12)+Inputs!$B$49*Inputs!$B$57/12)/Inputs!$B$3/(LayerCost!$B$12-((Inputs!$B$52-Inputs!$B$51)/1000*Inputs!$B$43/3600*Inputs!$B$53/Inputs!$B$3))/Breakeven!$B$4 | D25: =(Inputs!$B$49/(Inputs!$B$50*12)+Inputs!$B$51/1000*730*Inputs!$B$53+Inputs!$B$54*Inputs!$B$55+Inputs!$B$56/(Inputs!$B$50*12)+Inputs!$B$49*Inputs!$B$57/12)/Inputs!$B$3/(LayerCost!$B$12-((Inputs!$B$52-Inputs!$B$51)/1000*5/3600*Inputs!$B$53/Inputs!$B$3))/Breakeven!$B$4 | E25: 影響電費項；容量另見 TCO-Local 利用率
A27: 註：本機無 LibreOffice，本檔無快取值；Excel / Google Sheets 開啟即自動重算。公式已用 Python 鏡射驗證（見文件 §11）。
